{
  "uid" : "e4a74b78713f8bfb",
  "name" : "An uncaught error was detected outside of a test",
  "fullName" : "An uncaught error was detected outside of a test",
  "historyId" : "c59643030e1e776644fd5d1d6aa79cfc",
  "time" : {
    "start" : 1662776520668,
    "stop" : 1662776520810,
    "duration" : 142
  },
  "status" : "failed",
  "statusMessage" : "The following error originated from your test code, not from Cypress.\n\n  > Given is not defined\n\nWhen Cypress detects uncaught errors originating from your test code it will automatically fail the current test.\n\nCypress could not associate this error to any specific test.\n\nWe dynamically generated a new test to display this failure.",
  "statusTrace" : "ReferenceError: The following error originated from your test code, not from Cypress.\n\n  > Given is not defined\n\nWhen Cypress detects uncaught errors originating from your test code it will automatically fail the current test.\n\nCypress could not associate this error to any specific test.\n\nWe dynamically generated a new test to display this failure.\n    at eval (http://localhost:38869/__cypress/tests?p=cypress/e2e/cucumber/examples/steps.cy.js:6:1)\n    at eval (http://localhost:38869/__cypress/tests?p=cypress/e2e/cucumber/examples/steps.cy.js:45:12)\n    at eval (<anonymous>)",
  "flaky" : false,
  "newFailed" : false,
  "beforeStages" : [ ],
  "testStage" : {
    "status" : "failed",
    "statusMessage" : "The following error originated from your test code, not from Cypress.\n\n  > Given is not defined\n\nWhen Cypress detects uncaught errors originating from your test code it will automatically fail the current test.\n\nCypress could not associate this error to any specific test.\n\nWe dynamically generated a new test to display this failure.",
    "statusTrace" : "ReferenceError: The following error originated from your test code, not from Cypress.\n\n  > Given is not defined\n\nWhen Cypress detects uncaught errors originating from your test code it will automatically fail the current test.\n\nCypress could not associate this error to any specific test.\n\nWe dynamically generated a new test to display this failure.\n    at eval (http://localhost:38869/__cypress/tests?p=cypress/e2e/cucumber/examples/steps.cy.js:6:1)\n    at eval (http://localhost:38869/__cypress/tests?p=cypress/e2e/cucumber/examples/steps.cy.js:45:12)\n    at eval (<anonymous>)",
    "steps" : [ ],
    "attachments" : [ {
      "uid" : "a1925a2063c8c33",
      "name" : "cypress/e2e/cucumber/examples/steps.cy.js:2022-09-10T02:22:00.695Z",
      "source" : "a1925a2063c8c33.png",
      "type" : "image/png",
      "size" : 26563
    } ],
    "parameters" : [ ],
    "stepsCount" : 0,
    "attachmentsCount" : 1,
    "shouldDisplayMessage" : true,
    "hasContent" : true
  },
  "afterStages" : [ ],
  "labels" : [ {
    "name" : "resultFormat",
    "value" : "allure2"
  } ],
  "parameters" : [ ],
  "links" : [ ],
  "hidden" : false,
  "retry" : false,
  "extra" : {
    "severity" : "normal",
    "retries" : [ ],
    "categories" : [ {
      "name" : "Product defects",
      "matchedStatuses" : [ ],
      "flaky" : false
    } ],
    "history" : {
      "statistic" : {
        "failed" : 2,
        "broken" : 0,
        "skipped" : 0,
        "passed" : 0,
        "unknown" : 0,
        "total" : 2
      },
      "items" : [ {
        "uid" : "c9cea5e97a315c10",
        "status" : "failed",
        "statusDetails" : "The following error originated from your test code, not from Cypress.\n\n  > Given is not defined\n\nWhen Cypress detects uncaught errors originating from your test code it will automatically fail the current test.\n\nCypress could not associate this error to any specific test.\n\nWe dynamically generated a new test to display this failure.",
        "time" : {
          "start" : 1662776237426,
          "stop" : 1662776237582,
          "duration" : 156
        }
      } ]
    },
    "tags" : [ ]
  },
  "source" : "e4a74b78713f8bfb.json",
  "parameterValues" : [ ]
}